<?xml version="1.0" ?>
<!-- =================================================================================== -->
<!-- |    This document was autogenerated by xacro from kr210l150.xacro                | -->
<!-- |    EDITING THIS FILE BY HAND IS NOT RECOMMENDED                                 | -->
<!-- =================================================================================== -->
<!--Generates a urdf from the macro in kr210_macro.xacro -->
<robot name="kuka_kr210" xmlns:xacro="http://wiki.ros.org/xacro">
	<material name="black">
    <color rgba="0.0 0.0 0.0 1.0"/>
  </material>
  <material name="blue">
    <color rgba="0.0 0.0 0.8 1.0"/>
  </material>
  <material name="green">
    <color rgba="0.0 0.8 0.0 1.0"/>
  </material>
  <material name="grey">
    <color rgba="0.2 0.2 0.2 1.0"/>
  </material>
  <material name="orange">
    <color rgba="1.0 0.423529411765 0.0392156862745 1.0"/>
  </material>
  <material name="brown">
    <color rgba="0.870588235294 0.811764705882 0.764705882353 1.0"/>
  </material>
  <material name="red">
    <color rgba="0.8 0.0 0.0 1.0"/>
  </material>
  <material name="white">
    <color rgba="1.0 1.0 1.0 1.0"/>
  </material>
  <material name="metal">
    <color rgba="0.768627450980392 0.749019607843137 0.729411764705882 1"/>
  </material>
  <material name="metal_grey">
    <color rgba="0.501960784313725 0.501960784313725 0.501960784313725 1"/>
  </material>
  <material name="metal_white">
    <color rgba="0.866666666666667 0.866666666666667 0.890196078431373 1"/>
  </material>

  <link name="world">
  </link>
  <joint name="world_fixed" type="fixed">
    <origin rpy="0 0 0" xyz="0 0 0"/>
    <parent link="world"/>
    <child link="base_link"/>
  </joint>

  <link name="base_link">
    <inertial>
      <origin rpy="0 0 0" xyz="-0.027804 0.00039112 0.14035"/>
      <mass value="15.729"/>
      <inertia ixx="89.282" ixy="-0.47721" ixz="0.85562" iyy="107.51" iyz="0.0067576" izz="172.02"/>
    </inertial>
    <visual>
      <origin rpy="-1.570796327 0 0" xyz="0 0 0"/>
      <geometry>
        <mesh filename="C:/Users/whj03/Desktop/admittance/urdf/meshes/kr210l150/collision/base_link.stl"/>
      </geometry>
      <material name="black">
      </material>
    </visual>
    <collision>
      <origin rpy="-1.570796327 0 0" xyz="0 0 0"/>
      <geometry>
        <mesh filename="C:/Users/whj03/Desktop/admittance/urdf/meshes/kr210l150/collision/base_link.stl"/>
      </geometry>
    </collision>
  </link>

  <link name="link_1">
    <inertial>
      <origin rpy="0 0 0" xyz="-0.036811 -0.024697 0.56577"/>
      <mass value="138.55"/>
      <inertia ixx="90.873" ixy="33.809" ixz="17.159" iyy="147.03" iyz="0.063634" izz="168.19"/>
    </inertial>
    <visual>
      <origin rpy="0 0 0" xyz="0 0 0"/>
      <geometry>
        <mesh filename="C:/Users/whj03/Desktop/admittance/urdf/meshes/kr210l150/collision/link_1.stl"/>
      </geometry>
      <material name="orange">
      </material>
    </visual>
    <collision>
      <origin rpy="0 0 0" xyz="0 0 0"/>
      <geometry>
        <mesh filename="C:/Users/whj03/Desktop/admittance/urdf/meshes/kr210l150/collision/link_1.stl"/>
      </geometry>
    </collision>
  </link>
  <link name="link_2">
    <inertial>
      <origin rpy="0 0 0" xyz="0.016923 -0.19196 0.44751"/>
      <mass value="95.862"/>
      <inertia ixx="180.42" ixy="-0.83462" ixz="0.32549" iyy="177.68" iyz="-20.82" izz="20.495"/>
    </inertial>
    <visual>
      <origin rpy="0 0 0" xyz="0 0 0"/>
      <geometry>
        <mesh filename="C:/Users/whj03/Desktop/admittance/urdf/meshes/kr210l150/visual/link_2.dae"/>
      </geometry>
      <material name="">
        <color rgba="0.75294 0.75294 0.75294 1"/>
      </material>
    </visual>
    <collision>
      <origin rpy="0 0 0" xyz="0 0 0"/>
      <geometry>
        <mesh filename="C:/Users/whj03/Desktop/admittance/urdf/meshes/kr210l150/collision/link_2.stl"/>
      </geometry>
    </collision>
  </link>
  <link name="link_3">
    <inertial>
      <origin rpy="0 0 0" xyz="0.18842 0.18344 -0.042799"/>
      <mass value="71.003"/>
      <inertia ixx="11.887" ixy="-0.12154" ixz="-1.3604" iyy="98.805" iyz="-0.056505" izz="96.251"/>
    </inertial>
    <visual>
      <origin rpy="0 0 0" xyz="0 0 0"/>
      <geometry>
        <mesh filename="C:/Users/whj03/Desktop/admittance/urdf/meshes/kr210l150/collision/link_3.stl"/>
      </geometry>
      <material name="orange">
      </material>
    </visual>
    <collision>
      <origin rpy="0 0 0" xyz="0 0 0"/>
      <geometry>
        <mesh filename="C:/Users/whj03/Desktop/admittance/urdf/meshes/kr210l150/collision/link_3.stl"/>
      </geometry>
    </collision>
  </link>
  <link name="link_4">
    <inertial>
      <origin rpy="0 0 0" xyz="0.27146 -0.007326 5.2775E-05"/>
      <mass value="17.373"/>
      <inertia ixx="1.8001" ixy="-0.18515" ixz="0.00051232" iyy="5.514" iyz="0.00070469" izz="6.3498"/>
    </inertial>
    <visual>
      <origin rpy="0 0 0" xyz="0 0 0"/>
      <geometry>
        <mesh filename="C:/Users/whj03/Desktop/admittance/urdf/meshes/kr210l150/collision/link_4.stl"/>
      </geometry>
      <material name="black">
      </material>
    </visual>
    <collision>
      <origin rpy="0 0 0" xyz="0 0 0"/>
      <geometry>
        <mesh filename="C:/Users/whj03/Desktop/admittance/urdf/meshes/kr210l150/collision/link_4.stl"/>
      </geometry>
    </collision>
  </link>
  <link name="link_5">
    <inertial>
      <origin rpy="0 0 0" xyz="0.04379 0.025984 3.5491E-07"/>
      <mass value="7.217"/>
      <inertia ixx="0.3938" ixy="-0.085332" ixz="1.7223E-06" iyy="0.68945" iyz="-7.0292E-06" izz="0.67292"/>
    </inertial>
    <visual>
      <origin rpy="0 0 0" xyz="0 0 0"/>
      <geometry>
        <mesh filename="C:/Users/whj03/Desktop/admittance/urdf/meshes/kr210l150/collision/link_5.stl"/>
      </geometry>
      <material name="orange">
      </material>
    </visual>
    <collision>
      <origin rpy="0 0 0" xyz="0 0 0"/>
      <geometry>
        <mesh filename="C:/Users/whj03/Desktop/admittance/urdf/meshes/kr210l150/collision/link_5.stl"/>
      </geometry>
    </collision>
  </link>
  <link name="link_6">
    <inertial>
      <origin rpy="0 0 0" xyz="-0.017956 -1.5237E-05 0.00015484"/>
      <mass value="0.63154"/>
      <inertia ixx="0.031746" ixy="1.7673E-07" ixz="-6.6558E-06" iyy="0.016686" iyz="1.4304E-07" izz="0.016723"/>
    </inertial>
    <visual>
      <origin rpy="0 0 0" xyz="0 0 0"/>
      <geometry>
        <mesh filename="C:/Users/whj03/Desktop/admittance/urdf/meshes/kr210l150/visual/link_6.dae"/>
      </geometry>
      <material name="">
        <color rgba="0.75294 0.75294 0.75294 1"/>
      </material>
    </visual>
    <collision>
      <origin rpy="0 0 0" xyz="0 0 0"/>
      <geometry>
        <mesh filename="C:/Users/whj03/Desktop/admittance/urdf/meshes/kr210l150/collision/link_6.stl"/>
      </geometry>
    </collision>
  </link>
   <link name="eef"/>


  <joint name="joint_a1" type="revolute">
    <origin rpy="0 0 0" xyz="-0.00262 0.00097586 0.33099"/>
    <parent link="base_link"/>
    <child link="link_1"/>
    <axis xyz="0 0 1"/>
    <limit effort="0" lower="-3.228859205" upper="3.228859205" velocity="2.146755039"/>
  </joint>
  <joint name="joint_a2" type="revolute">
    <origin rpy="0 0 0" xyz="0.35277 -0.037476 0.4192"/>
    <parent link="link_1"/>
    <child link="link_2"/>
    <axis xyz="0 1 0"/>
    <limit effort="0" lower="-0.785398185" upper="1.483529905" velocity="2.007128695"/>
  </joint>
  <joint name="joint_a3" type="revolute">
    <origin rpy="0 0 0" xyz="-9.8483E-05 -0.1475 1.2499"/>
    <parent link="link_2"/>
    <child link="link_3"/>
    <axis xyz="0 1 0"/>
    <limit effort="0" lower="-3.66519153" upper="1.134464045" velocity="1.954768816"/>
  </joint>
  <joint name="joint_a4" type="revolute">
    <origin rpy="0 0 0" xyz="0.95795 0.184 -0.055059"/>
    <parent link="link_3"/>
    <child link="link_4"/>
    <axis xyz="1 0 0"/>
    <limit effort="0" lower="-6.10865255" upper="6.10865255" velocity="3.124139447"/>
  </joint>
  <joint name="joint_a5" type="revolute">
    <origin rpy="0 0 0" xyz="0.542 0 0"/>
    <parent link="link_4"/>
    <child link="link_5"/>
    <axis xyz="0 1 0"/>
    <limit effort="0" lower="-2.181661625" upper="2.181661625" velocity="3.001966396"/>
  </joint>

  <joint name="joint_a6" type="revolute">
    <origin rpy="0 0 0" xyz="0.1925 0 0"/>
    <parent link="link_5"/>
    <child link="link_6"/>
    <axis xyz="1 0 0"/>
    <limit effort="0" lower="-6.10865255" upper="6.10865255" velocity="3.822271167"/>
  </joint>

  <joint name="r_fixed_eef" type="fixed">
 		<origin rpy="0 0 0" xyz="0 0 0"/>
		<axis xyz="0 0 1"/>
 		<parent link="link_6"/>
		<child link="eef"/>
 	</joint>
</robot>

